Workbook
Name _Toc215175183: 'Q1'!#REF!
Name _Toc215175183: 'Q2'!#REF!
Name _Toc215175183: 'Q3'!#REF!
Name _Toc215175183: 'Q4'!#REF!
Name _Toc215175183: 'Q5'!#REF!
Name _Toc215175183: 'Q6'!#REF!
Name _Toc215175183: 'Q7'!#REF!
Name _Toc215175183: 'Q8'!#REF!

Sheet Índice
C5: Direcção das Contas Nacionais
C6: Departamento das Contas Nacionais
C7: Contas Nacionais Anuais - 2002 - 2025
B13: Índice
B14: Q1 | C14: =+'Q1'!A2 -> Quadro 1- Produto Interno Bruto (PIB) por Províncias, a preços correntes em mill milhões de Kwanzas: 2015 - 2025
B15: Q2 | C15: =+'Q2'!A1 -> Quadro 2 - Estrutura Percentual do PIB por província: 2015 – 2025*
B16: Q3 | C16: =+'Q3'!A2 -> Quadro 3- Produto Interno Bruto (PIB) por Províncias a preços do ano anterior em mil milhões de Kwanzas: 2015 - 2025
B17: Q4 | C17: =+'Q4'!A2 -> Quadro 4- PIB por província, variações percentuais de preços 2015 - 2025*
B18: Q5 | C18: =+'Q5'!A1 -> Quadro 5- Produto Interno Bruto (PIB) per Capita por Províncias, a preços correntes em milhares de Kwanzas: 2015 - 2025*
B19: Q6 | C19: Quadro 6- Produto Interno Bruto por Província e por sectores de actividades à preços correntes(valores em milhões de kwanzas)
B20: Q7 | C20: =+'Q7'!A2 -> Quadro 7- Participação dos principais sectores de actividades no VAB por província em 2025* (%)
B21: Q8 | C21: =+'Q8'!A2 -> Quadro 8 - PIB por província, variações percentuais de volume 2015 - 2025*

Sheet Q1
A2: Quadro 1- Produto Interno Bruto (PIB) por Províncias, a preços correntes em mill milhões de Kwanzas: 2015 - 2025
A3: Províncias | B3: 2015 | C3: 2016 | D3: 2017 | E3: 2018 | F3: 2019 | G3: 2020 | H3: 2021 | I3: 2022 | J3: 2023 | K3: 2024 | L3: 2025
A4: Luanda | B4: 5735.1983 | C4: 6792.4489 | D4: 8466.0734 | E4: 9989.831 | F4: 11347.975 | G4: 12494.604 | H4: 15779.892 | I4: 20455.97 | J4: 24223.383 | K4: 32289.425 | L4: 40810.255
A5: Zaire | B5: 2215.1119 | C5: 2527.8572 | D5: 3200.4484 | E5: 5523.1339 | F5: 7011.6105 | G5: 6584.6422 | H5: 10807.482 | I5: 11914.915 | J5: 14045.515 | K5: 18417.765 | L5: 18070.9
A6: Benguela | B6: 918.62535 | C6: 1166.4784 | D6: 1376.8083 | E6: 1461.4906 | F6: 1816.1677 | G6: 2088.8995 | H6: 2735.2434 | I6: 3953.1819 | J6: 4632.0874 | K6: 7832.6565 | L6: 10248.672
A7: Uige | B7: 787.76597 | C7: 966.27516 | D7: 1229.5739 | E7: 1391.7724 | F7: 1638.5422 | G7: 2023.7259 | H7: 2818.8071 | I7: 3715.6158 | J7: 4430.2209 | K7: 6046.64 | L7: 8541.7431
A8: Cabinda | B8: 1056.2297 | C8: 1220.5893 | D8: 1509.9702 | E8: 2141.259 | F8: 2466.5149 | G8: 2648.8684 | H8: 3489.0471 | I8: 3733.3869 | J8: 4242.8106 | K8: 5193.8559 | L8: 5447.1335
A9: Cuanza Sul | B9: 697.00805 | C9: 879.35218 | D9: 1122.2418 | E9: 1223.9785 | F9: 1414.2293 | G9: 2000.1572 | H9: 2609.8161 | I9: 2887.6152 | J9: 3398.233 | K9: 4615.7572 | L9: 6176.8206
A10: Malanje | B10: 555.49656 | C10: 681.30764 | D10: 852.21501 | E10: 970.69668 | F10: 1118.4061 | G10: 1392.0194 | H10: 2034.3654 | I10: 2352.3178 | J10: 3271.5452 | K10: 4357.9844 | L10: 6102.8197
A11: Huambo | B11: 558.56242 | C11: 758.6715 | D11: 806.99796 | E11: 900.81504 | F11: 1103.9563 | G11: 1282.149 | H11: 1678.1273 | I11: 2160.2992 | J11: 2886.0039 | K11: 3567.6597 | L11: 4717.974
A12: Huíla | B12: 476.4526 | C12: 588.35043 | D12: 722.82167 | E12: 794.42502 | F12: 1001.6652 | G12: 1107.4303 | H12: 1372.4613 | I12: 1943.6557 | J12: 2477.749 | K12: 3269.3886 | L12: 4134.4627
A13: Lunda Sul | B13: 407.34744 | C13: 501.63642 | D13: 610.79232 | E13: 713.93031 | F13: 972.81728 | G13: 1316.3938 | H13: 1582.3828 | I13: 1750.2769 | J13: 2363.1286 | K13: 3089.0282 | L13: 3720.1121
A14: Bié | B14: 382.78343 | C14: 486.54233 | D14: 577.9553 | E14: 655.66181 | F14: 853.71792 | G14: 867.25376 | H14: 1313.2174 | I14: 1695.5679 | J14: 2087.504 | K14: 2961.7526 | L14: 3893.1262
... A22: ANGOLA | B22: 15807.317 | C22: 19061.544 | D22: 23545.238 | E22: 29193.781 | F22: 34735.035 | G22: 38243.647 | H22: 52423.748 | I22: 64097.477 | J22: 77499.868 | K22: 104011.09 | L22: 128302.02

Sheet Q2
A1: Quadro 2 - Estrutura Percentual do PIB por província: 2015 – 2025*
A2: Províncias | B2: 2015 | C2: 2016 | D2: 2017 | E2: 2018 | F2: 2019 | G2: 2020 | H2: 2021 | I2: 2022 | J2: 2023 | K2: 2024 | L2: 2025
A3: Luanda | B3: 36.28192 | C3: 35.634306 | D3: 35.956626 | E3: 34.219038 | F3: 32.670113 | G3: 32.671059 | H3: 30.100656 | I3: 31.913845 | J3: 31.256032 | K3: 31.044215 | L3: 31.80796
A4: Zaire | B4: 14.013206 | C4: 13.261555 | D4: 13.592763 | E4: 18.918871 | F4: 20.18599 | G4: 17.217611 | H4: 20.615621 | I4: 18.588742 | J4: 18.123276 | K4: 17.707501 | L4: 14.084657
A5: Benguela | B5: 5.8113931 | C5: 6.119538 | D5: 5.8475022 | E5: 5.006171 | F5: 5.2286335 | G5: 5.4620825 | H5: 5.2175655 | I5: 6.1674531 | J5: 5.9768971 | K5: 7.5305976 | L5: 7.9879272
A6: Uíge | B6: 4.9835526 | C6: 5.0692387 | D6: 5.2221764 | E6: 4.7673591 | F6: 4.717261 | G6: 5.2916655 | H6: 5.376966 | I6: 5.7968206 | J6: 5.7164239 | K6: 5.8134572 | L6: 6.6575281
A7: Cabinda | B7: 6.6819036 | C7: 6.4034124 | D7: 6.4130596 | E7: 7.3346408 | F7: 7.1009427 | G7: 6.9262966 | H7: 6.6554705 | I7: 5.8245458 | J7: 5.4746037 | K7: 4.9935598 | L7: 4.2455554
A8: Cuanza Sul | B8: 4.4094012 | C8: 4.6132264 | D8: 4.7663215 | E8: 4.1926001 | F8: 4.0714779 | G8: 5.2300377 | H8: 4.9783087 | I8: 4.5050371 | J8: 4.3848243 | K8: 4.4377549 | L8: 4.8142816
A9: Malanje | B9: 3.5141735 | C9: 3.5742521 | D9: 3.6194792 | E9: 3.3250118 | F9: 3.2198215 | G9: 3.639871 | H9: 3.880618 | I9: 3.669907 | J9: 4.2213559 | K9: 4.1899229 | L9: 4.7566045
A10: Huambo | B10: 3.5335687 | C10: 3.9801157 | D10: 3.4274359 | E10: 3.0856402 | F10: 3.1782215 | G10: 3.3525802 | H10: 3.2010822 | I10: 3.3703343 | J10: 3.7238824 | K10: 3.4300764 | L10: 3.6772406
A11: Huíla | B11: 3.0141269 | C11: 3.0865833 | D11: 3.0699271 | E11: 2.7212132 | F11: 2.8837317 | G11: 2.8957237 | H11: 2.6180144 | I11: 3.0323435 | J11: 3.1971009 | K11: 3.1433078 | L11: 3.2224455
A12: Lunda Sul | B12: 2.5769549 | C12: 2.6316673 | D12: 2.5941225 | E12: 2.4454876 | F12: 2.8006803 | G12: 3.4421242 | H12: 3.0184464 | I12: 2.7306487 | J12: 3.0492034 | K12: 2.9699028 | L12: 2.8994961
A13: Bié | B13: 2.4215584 | C13: 2.5524812 | D13: 2.4546589 | E13: 2.2458955 | F13: 2.4578007 | G13: 2.2677067 | H13: 2.5050047 | I13: 2.6452958 | J13: 2.6935581 | K13: 2.8475355 | L13: 3.0343452
... A21: ANGOLA | B21: 100 | C21: 100 | D21: 100 | E21: 100 | F21: 100 | G21: 100 | H21: 100 | I21: 100 | J21: 100 | K21: 100 | L21: 100

Sheet Q3
A2: Quadro 3- Produto Interno Bruto (PIB) por Províncias a preços do ano anterior em mil milhões de Kwanzas: 2015 - 2025
A3: Províncias | B3: 2015 | C3: 2016 | D3: 2017 | E3: 2018 | F3: 2019 | G3: 2020 | H3: 2021 | I3: 2022 | J3: 2023 | K3: 2024 | L3: 2025
A4: Bengo | B4: 272.90591 | C4: 296.41428 | D4: 384.62419 | E4: 465.25192 | F4: 471.86328 | G4: 607.22027 | H4: 730.94131 | I4: 940.10619 | J4: 1356.3504 | K4: 1724.6611 | L4: 2321.0442
A5: Benguela | B5: 841.17529 | C5: 964.20795 | D5: 1138.4121 | E5: 1304.8114 | F5: 1561.1549 | G5: 1736.8747 | H5: 2163.109 | I5: 3170.3754 | J5: 3909.9131 | K5: 6167.0701 | L5: 8146.4592
A6: Bié | B6: 344.81403 | C6: 389.08948 | D6: 471.82768 | E6: 584.90514 | F6: 741.30023 | G6: 707.91978 | H6: 1016.0052 | I6: 1326.038 | J6: 1724.9225 | K6: 2269.815 | L6: 2980.0986
A7: Cabinda | B7: 1388.7102 | C7: 1036.6922 | D7: 1168.3735 | E7: 1411.3594 | F7: 1979.1657 | G7: 2442.8304 | H7: 2194.4479 | I7: 3421.2558 | J7: 3521.78 | K7: 4196.2297 | L7: 4945.5837
A8: Cuando Cubango | B8: 146.02874 | C8: 160.11265 | D8: 205.35202 | E8: 240.61113 | F8: 278.82742 | G8: 245.45512 | H8: 340.20386 | I8: 406.93091 | J8: 497.13757 | K8: 498.71382 | L8: 634.69626
A9: Cuanza Norte | B9: 311.8075 | C9: 348.45226 | D9: 438.88354 | E9: 535.22058 | F9: 610.48764 | G9: 656.62335 | H9: 884.22951 | I9: 1103.2381 | J9: 1561.8942 | K9: 1809.5916 | L9: 2473.2949
A10: Cuanza Sul | B10: 629.90657 | C10: 708.5781 | D10: 911.16405 | E10: 1088.9964 | F10: 1230.6318 | G10: 1644.131 | H10: 2011.5919 | I10: 2256.8319 | J10: 2816.9921 | K10: 3560.2964 | L10: 4721.7914
A11: Cunene | B11: 180.88327 | C11: 204.9708 | D11: 251.91655 | E11: 311.52149 | F11: 351.22336 | G11: 320.80478 | H11: 415.80663 | I11: 475.8893 | J11: 637.54488 | K11: 681.6126 | L11: 907.149
A12: Huambo | B12: 506.89047 | C12: 628.5672 | D12: 660.55072 | E12: 802.83353 | F12: 965.70928 | G12: 1063.5091 | H12: 1316.0879 | I12: 1725.3782 | J12: 2430.9758 | K12: 2744.9885 | L12: 3675.3269
A13: Huíla | B13: 431.61245 | C13: 479.33999 | D13: 598.21324 | E13: 714.25214 | F13: 859.27853 | G13: 924.23562 | H13: 1096.1169 | I13: 1550.6221 | J13: 2077.2513 | K13: 2541.446 | L13: 3288.5382
A14: Luanda | B14: 5104.9404 | C14: 5649.5785 | D14: 7035.9668 | E14: 8823.016 | F14: 9602.2757 | G14: 10476.094 | H14: 12894.667 | I14: 16926.763 | J14: 20598.729 | K14: 25115.7 | L14: 33695.233
... A22: ANGOLA | B22: 16289.041 | C22: 15770.474 | D22: 19030.152 | E22: 23425.935 | F22: 28885.718 | G22: 32903.286 | H22: 38660.726 | I22: 54288.719 | J22: 64943.67 | K22: 81338.187 | L22: 107270.31

Sheet Q4
A2: Quadro 4- PIB por província, variações percentuais de preços 2015 - 2025*
A3: Provincias | B3: 2015 | C3: 2016 | D3: 2017 | E3: 2018 | F3: 2019 | G3: 2020 | H3: 2021 | I3: 2022 | J3: 2023 | K3: 2024 | L3: 2025
A4: Bengo | B4: 11.13503 | C4: 23.760953 | D4: 22.71852 | E4: 9.2534713 | F4: 14.706648 | G4: 20.267307 | H4: 29.377964 | I4: 26.495224 | J4: 19.382821 | K4: 30.428353 | L4: 26.63841
A5: Benguela | B5: 9.2073622 | C5: 20.97789 | D5: 20.941119 | E5: 12.007807 | F5: 16.334879 | G5: 20.267714 | H5: 26.449635 | I5: 24.691286 | J5: 18.47034 | K5: 27.007743 | L5: 25.805235
A6: Bié | B6: 11.011557 | C6: 25.046384 | D6: 22.492878 | E6: 12.097119 | F6: 15.164935 | G6: 22.507349 | H6: 29.253016 | I6: 27.867215 | J6: 21.020163 | K6: 30.484316 | L6: 30.637498
A7: Cabinda | B7: -23.941677 | C7: 17.738828 | D7: 29.236941 | E7: 51.71607 | F7: 24.623972 | G7: 8.4343987 | H7: 58.994298 | I7: 9.1232919 | J7: 20.473471 | K7: 23.774347 | L7: 10.141366
A8: Cuando Cubango | B8: 11.331962 | C8: 23.087389 | D8: 18.540863 | E8: 5.3768645 | F8: 14.111571 | G8: 14.834565 | H8: 20.646757 | I8: 18.759442 | J8: 15.074716 | K8: 26.483186 | L8: 20.425975
A9: Cuanza Norte | B9: 10.874873 | C9: 24.630418 | D9: 23.976827 | E9: 11.415165 | F9: 15.509018 | G9: 21.708959 | H9: 28.507895 | I9: 26.813804 | J9: 19.613779 | K9: 30.593995 | L9: 29.006024
A10: Cuanza Sul | B10: 10.652608 | C10: 24.100953 | D10: 23.16572 | E10: 12.395092 | F10: 14.918961 | G10: 21.654369 | H10: 29.738842 | I10: 27.949942 | J10: 20.633388 | K10: 29.645304 | L10: 30.815195
A11: Cunene | B11: 13.251306 | C11: 22.558097 | D11: 17.886744 | E11: 6.2279902 | F11: 14.967451 | G11: 13.857295 | H11: 18.400102 | I11: 17.321794 | J11: 12.64942 | K11: 21.991779 | L11: 15.172306
A12: Huambo | B12: 10.193908 | C12: 20.69855 | D12: 22.170476 | E12: 12.204462 | F12: 14.315598 | G12: 20.558342 | H12: 27.508756 | I12: 25.207285 | J12: 18.71792 | K12: 29.969934 | L12: 28.368828
A13: Huíla | B13: 10.388985 | C13: 22.741778 | D13: 20.830102 | E13: 11.22473 | F13: 16.570494 | G13: 19.821215 | H13: 25.211213 | I13: 25.346833 | J13: 19.280173 | K13: 28.642855 | L13: 25.72342
A14: Luanda | B14: 12.346038 | C14: 20.229305 | D14: 20.325659 | E14: 13.224673 | F14: 18.180061 | G14: 19.267782 | H14: 22.375339 | I14: 20.849862 | J14: 17.596493 | K14: 28.562715 | L14: 21.115811
... A22: ANGOLA | B22: -2.9573458 | C22: 20.868554 | D22: 23.725963 | E22: 24.621624 | F22: 20.249856 | G22: 16.23048 | H22: 35.599493 | I22: 18.067765 | J22: 19.333981 | K22: 27.874854 | L22: 19.606273

Sheet Q5
A1: Quadro 5- Produto Interno Bruto (PIB) per Capita por Províncias, a preços correntes em milhares de Kwanzas: 2015 - 2025*
A2: Províncias | B2: 2015 | C2: 2016 | D2: 2017 | E2: 2018 | F2: 2019 | G2: 2020 | H2: 2021 | I2: 2022 | J2: 2023 | K2: 2024 | L2: 2025
A3: Zaire | B3: 3598.6131 | C3: 3979.8183 | D3: 4882.1856 | E3: 8162.4799 | F3: 10037.795 | G3: 9133.8936 | H3: 14535.191 | I3: 15545.992 | J3: 17788.815 | K3: 26979.503 | L3: 25830.314
A4: Cabinda | B4: 1431.6964 | C4: 1609.915 | D4: 1937.3917 | E4: 2671.9846 | F4: 2992.824 | G4: 3125.9621 | H4: 4006.9125 | I4: 4174.7591 | J4: 4622.221 | K4: 5749.4235 | L4: 5883.7647
A5: Cuanza Norte | B5: 757.01729 | C5: 925.60762 | D5: 1128.3473 | E5: 1202.7125 | F5: 1382.767 | G5: 1523.4782 | H5: 2106.2729 | I5: 2521.9661 | J5: 3275.4029 | K5: 3585.5393 | L5: 4723.7781
A6: Lunda Sul | B6: 732.41271 | C6: 874.92792 | D6: 1033.0753 | E6: 1170.6635 | F6: 1546.0858 | G6: 2027.9262 | H6: 2363.8363 | I6: 2536.3649 | J6: 3323.0613 | K6: 3455.5354 | L6: 4060.7138
A7: Malanje | B7: 546.17875 | C7: 651.29468 | D7: 791.66749 | E7: 875.87134 | F7: 979.7817 | G7: 1183.8047 | H7: 1679.6197 | I7: 1885.6119 | J7: 2546.2369 | K7: 3356.8142 | L7: 4586.961
A8: Luanda | B8: 794.83053 | C8: 910.40965 | D8: 1097.403 | E8: 1252.3439 | F8: 1375.8977 | G8: 1465.8879 | H8: 1792.9587 | I8: 2252.907 | J8: 2588.0922 | K8: 3169.0578 | L8: 3908.3374
A9: Bengo | B9: 789.78922 | C9: 920.56729 | D9: 1141.2144 | E9: 1183.9689 | F9: 1214.4283 | G9: 1578.6654 | H9: 1970.4231 | I9: 2389.2692 | J9: 3138.281 | K9: 3140.2144 | L9: 4003.9188
A10: Benguela | B10: 400.43074 | C10: 495.75822 | D10: 570.32093 | E10: 589.88278 | F10: 714.04469 | G10: 800.01545 | H10: 1020.75 | I10: 1437.8867 | J10: 1642.5044 | K10: 3015.2995 | L10: 3849.8326
A11: Uige | B11: 515.60763 | C11: 615.21071 | D11: 761.17639 | E11: 837.38449 | F11: 957.75817 | G11: 1148.9518 | H11: 1554.4012 | I11: 1989.9857 | J11: 2304.1989 | K11: 2996.4694 | L11: 4130.4286
A12: Moxico | B12: 501.64233 | C12: 597.39551 | D12: 717.25008 | E12: 815.56581 | F12: 902.49156 | G12: 992.16 | H12: 1465.7233 | I12: 1862.6243 | J12: 2063.1462 | K12: 2772.8041 | L12: 3693.8561
A13: Cuanza Sul | B13: 359.48559 | C13: 441.12895 | D13: 547.31727 | E13: 580.08487 | F13: 651.0633 | G13: 894.2923 | H13: 1133.3288 | I13: 1217.922 | J13: 1392.0612 | K13: 1982.7296 | L13: 2589.0379
... A21: ANGOLA | B21: 592.44285 | C21: 693.05819 | D21: 830.23774 | E21: 998.07768 | F21: 1151.0985 | G21: 1228.606 | H21: 1633.2571 | I21: 1937.2828 | J21: 2273.1182 | K21: 2841.4696 | L21: 3420.1863

Sheet Q6
B2: Quadro 6- Produto Interno Bruto por Província e por sectores de actividades à preços correntes(valores em milhões de kwanzas)
A3: Províncias | B3: 2015 | G3: 2016 | L3: 2017 | Q3: 2018 | V3: 2019 | AA3: 2020 | AF3: 2021 | AK3: 2022 | AP3: 2023 | AU3: 2024 | AZ3: 2025
B4: Agropecuária | C4: Indústria | D4: Serviços | E4: Impostos sobre os Produtos | F4: Produto Interno Bruto | G4: Agropecuária | H4: Indústria | I4: Serviços | J4: Impostos sobre os Produtos | K4: Produto Interno Bruto | L4: Agropecuária | M4: Indústria | N4: Serviços | O4: Impostos sobre os Produtos | P4: Produto Interno Bruto | Q4: Agropecuária | R4: Indústria | S4: Serviços | T4: Impostos sobre os Produtos | U4: Produto Interno Bruto | V4: Agropecuária | W4: Indústria | X4: Serviços | Y4: Impostos sobre os Produtos | Z4: Produto Interno Bruto | AA4: Agropecuária | AB4: Indústria | AC4: Serviços | AD4: Impostos sobre os Produtos | AE4: Produto Interno Bruto | AF4: Agropecuária | AG4: Indústria | AH4: Serviços | AI4: Impostos sobre os Produtos | AJ4: Produto Interno Bruto | AK4: Agropecuária | AL4: Indústria | AM4: Serviços | AN4: Impostos sobre os Produtos | AO4: Produto Interno Bruto | AP4: Agropecuária | AQ4: Indústria | AR4: Serviços | AS4: Impostos sobre os Produtos | AT4: Produto Interno Bruto | AU4: Agropecuária | AV4: Indústria | AW4: Serviços | AX4: Impostos sobre os Produtos | AY4: Produto Interno Bruto | AZ4: Agropecuária | BA4: Indústria | BB4: Serviços | BC4: Impostos sobre os Produtos | BD4: Produto Interno Bruto
A5: Bengo | B5: 96864.302 | C5: 110676.99 | D5: 95336.31 | E5: 416.46516 | F5: 303294.07 | G5: 123582.55 | H5: 131938.38 | I5: 110467.77 | J5: 856.44238 | K5: 366845.14 | L5: 155658.05 | M5: 174052.06 | N5: 141183.15 | O5: 1111.8577 | P5: 472005.12 | Q5: 171289.05 | R5: 173023.08 | S5: 162486.58 | T5: 1505.1592 | U5: 508303.88 | V5: 189606.58 | W5: 159334.68 | X5: 191003.15 | Y5: 1314.1441 | Z5: 541258.55 | AA5: 258778.73 | AB5: 231296.03 | AC5: 238687.92 | AD5: 1524.7901 | AE5: 730287.47 | AF5: 385939.51 | AG5: 201416.85 | AH5: 356810.17 | AI5: 1510.4572 | AJ5: 945676.99 | AK5: 557039.36 | AL5: 206215.86 | AM5: 425801.33 | AN5: 132.88164 | AO5: 1189189.4 | AP5: 764453.06 | AQ5: 339233.76 | AR5: 515828.78 | AS5: -266.1821 | AT5: 1619249.4 | AU5: 1029456.2 | AV5: 557708.96 | AW5: 662308.63 | AX5: -26.770149 | AY5: 2249447 | AZ5: 1432395.8 | BA5: 458917.08 | BB5: 1046915.6 | BC5: 1104.9996 | BD5: 2939333.4
A6: Benguela | B6: 171810.69 | C6: 213596.23 | D6: 526696.31 | E6: 6522.1163 | F6: 918625.35 | G6: 220022.57 | H6: 298989.5 | I6: 634053.92 | J6: 13412.447 | K6: 1166478.4 | L6: 275267.4 | M6: 339924.58 | N6: 744203.94 | O6: 17412.418 | P6: 1376808.3 | Q6: 296762.75 | R6: 284593.11 | S6: 856562.98 | T6: 23571.775 | U6: 1461490.6 | V6: 326315.09 | W6: 453151.1 | X6: 1016121.1 | Y6: 20580.355 | Z6: 1816167.7 | AA6: 432561.37 | AB6: 441359.74 | AC6: 1191099.2 | AD6: 23879.208 | AE6: 2088899.5 | AF6: 665212.84 | AG6: 625332.61 | AH6: 1428447.6 | AI6: 16250.364 | AJ6: 2735243.4 | AK6: 1013650.9 | AL6: 934403.76 | AM6: 2002934.1 | AN6: 2193.1303 | AO6: 3953181.9 | AP6: 1275947.7 | AQ6: 969538.67 | AR6: 2389566.7 | AS6: -2965.7296 | AT6: 4632087.4 | AU6: 1598387.4 | AV6: 1286482.6 | AW6: 4949178.8 | AX6: -1392.2864 | AY6: 7832656.5 | AZ6: 2309262.4 | BA6: 1510737.9 | BB6: 6406657.3 | BC6: 22014.43 | BD6: 10248672
A7: Bié | B7: 137064.98 | C7: 77729.35 | D7: 167915.91 | E7: 73.190341 | F7: 382783.43 | G7: 174707.51 | H7: 103553.47 | I7: 208130.84 | J7: 150.51273 | K7: 486542.33 | L7: 220271.39 | M7: 117897.39 | N7: 239591.12 | O7: 195.39989 | P7: 577955.3 | Q7: 247734.05 | R7: 116250.31 | S7: 291412.93 | T7: 264.51939 | U7: 655661.81 | V7: 278409.72 | W7: 199445.59 | X7: 375631.67 | Y7: 230.95007 | Z7: 853717.92 | AA7: 378781.64 | AB7: 125250.1 | AC7: 362954.05 | AD7: 267.96937 | AE7: 867253.76 | AF7: 565426.19 | AG7: 119576.58 | AH7: 628050.23 | AI7: 164.37426 | AJ7: 1313217.4 | AK7: 799784.24 | AL7: 131554.96 | AM7: 764176.88 | AN7: 51.825384 | AO7: 1695567.9 | AP7: 1033876.9 | AQ7: 144255.23 | AR7: 909396.26 | AS7: -24.386423 | AT7: 2087504 | AU7: 1455154.3 | AV7: 191435.48 | AW7: 1315169.2 | AX7: -6.3956776 | AY7: 2961752.6 | AZ7: 2051372.8 | BA7: 198397.36 | BB7: 1643121.2 | BC7: 234.89157 | BD7: 3893126.2
A8: Cabinda | B8: 71819.698 | C8: 723055.08 | D8: 259536.89 | E8: 1818.0361 | F8: 1056229.7 | G8: 91822.319 | H8: 832717.3 | I8: 292310.95 | J8: 3738.7117 | K8: 1220589.3 | L8: 115908.73 | M8: 1010448.5 | N8: 378759.28 | O8: 4853.7013 | P8: 1509970.2 | Q8: 128161.28 | R8: 1619254.2 | S8: 387272.88 | T8: 6570.6184 | U8: 2141259 | V8: 145869.42 | W8: 1903685 | X8: 411223.79 | Y8: 5736.7618 | Z8: 2466514.9 | AA8: 198697.82 | AB8: 1598652.6 | AC8: 844861.74 | AD8: 6656.3153 | AE8: 2648868.4 | AF8: 281533.85 | AG8: 2543107.3 | AH8: 660679.11 | AI8: 3726.8598 | AJ8: 3489047.1 | AK8: 443750.67 | AL8: 2595434.3 | AM8: 693656.04 | AN8: 545.91935 | AO8: 3733386.9 | AP8: 555248.06 | AQ8: 2909234.1 | AR8: 779371.76 | AS8: -1043.3354 | AT8: 4242810.6 | AU8: 749159.37 | AV8: 3372766 | AW8: 1072338.2 | AX8: -407.70539 | AY8: 5193855.9 | AZ8: 1120517 | BA8: 2933892.1 | BB8: 1386166 | BC8: 6558.3928 | BD8: 5447133.5
A9: Cuando Cubango | B9: 13124.633 | C9: 93645.921 | D9: 55723.87 | E9: 82.234019 | F9: 162576.66 | G9: 16713.195 | H9: 119158.62 | I9: 61037.549 | J9: 169.11066 | K9: 197078.48 | L9: 21122.538 | M9: 141511.74 | N9: 80572.235 | O9: 219.54425 | P9: 243426.06 | Q9: 23711.702 | R9: 145660.71 | S9: 83878.846 | T9: 297.20442 | U9: 253548.46 | V9: 26560.615 | W9: 172001.74 | X9: 119352.5 | Y9: 259.48714 | Z9: 318174.35 | AA9: 36593.469 | AB9: 127351.93 | AC9: 117620.84 | AD9: 301.08069 | AE9: 281867.32 | AF9: 53810.934 | AG9: 165231.03 | AH9: 191273.46 | AI9: 129.4982 | AJ9: 410444.93 | AK9: 75539.445 | AL9: 177339.21 | AM9: 230353.53 | AN9: 36.688593 | AO9: 483268.88 | AP9: 103653.7 | AQ9: 235088.99 | AR9: 233397.21 | AS9: -60.256759 | AT9: 572079.64 | AU9: 140481.67 | AV9: 191834.66 | AW9: 298483.54 | AX9: -10.736486 | AY9: 630789.12 | AZ9: 186801.14 | BA9: 187815.02 | BB9: 389421.9 | BC9: 301.09643 | BD9: 764339.16
A10: Cuanza Norte | B10: 95140.732 | C10: 106067.47 | D10: 144363.69 | E10: 144.27882 | F10: 345716.17 | G10: 121268.34 | H10: 141557.76 | I10: 171154.71 | J10: 296.70308 | K10: 434277.51 | L10: 153132.48 | M10: 170065.76 | N10: 220530.46 | O10: 385.18834 | P10: 544113.88 | Q10: 171683.23 | R10: 162221.16 | S10: 261891.06 | T10: 521.44239 | U10: 596316.89 | V10: 193224.81 | W10: 203770.27 | X10: 307717.93 | Y10: 455.26777 | Z10: 705168.28 | AA10: 264480.89 | AB10: 150538.34 | AC10: 383621.98 | AD10: 528.24327 | AE10: 799169.45 | AF10: 388243.87 | AG10: 178503.04 | AH10: 569180.72 | AI10: 377.11153 | AJ10: 1136304.7 | AK10: 557620.55 | AL10: 173553 | AM10: 667804.92 | AN10: 79.730854 | AO10: 1399058.2 | AP10: 735351.1 | AQ10: 279416.94 | AR10: 853530.17 | AS10: -57.517479 | AT10: 1868240.7 | AU10: 1016247.1 | AV10: 304471.54 | AW10: 1042515.6 | AX10: -16.37392 | AY10: 2363217.9 | AZ10: 1474949.4 | BA10: 353555.45 | BB10: 1361744.5 | BC10: 450.10001 | BD10: 3190699.4
A11: Cuanza Sul | B11: 250083.43 | C11: 163035.88 | D11: 283639.05 | E11: 249.69096 | F11: 697008.05 | G11: 319270.52 | H11: 224275.94 | I11: 335292.24 | J11: 513.47853 | K11: 879352.18 | L11: 400795.11 | M11: 299945.34 | N11: 420834.69 | O11: 666.61236 | P11: 1122241.8 | Q11: 448731.26 | R11: 277956.73 | S11: 496388.1 | T11: 902.41554 | U11: 1223978.5 | V11: 502368.88 | W11: 296144.3 | X11: 614928.2 | Y11: 787.89281 | Z11: 1414229.3 | AA11: 670148.64 | AB11: 483119.23 | AC11: 845975.11 | AD11: 914.18524 | AE11: 2000157.2 | AF11: 1030746.4 | AG11: 587761.96 | AH11: 990618.73 | AI11: 689.00158 | AJ11: 2609816.1 | AK11: 1468819 | AL11: 256496.5 | AM11: 1162200.8 | AN11: 98.918488 | AO11: 2887615.2 | AP11: 1777333.4 | AQ11: 332319.06 | AR11: 1288722.4 | AS11: -141.83025 | AT11: 3398233 | AU11: 2574293 | AV11: 467713.56 | AW11: 1573780.7 | AX11: -30.06034 | AY11: 4615757.2 | AZ11: 3480902.3 | BA11: 444200.07 | BB11: 2250941.9 | BC11: 776.3141 | BD11: 6176820.6
A12: Cunene | B12: 5293.6651 | C12: 117904 | D12: 77772.182 | E12: 3882.8256 | F12: 204852.67 | G12: 6752.0679 | H12: 146615.78 | I12: 89855.598 | J12: 7984.861 | K12: 251208.31 | L12: 8701.3359 | M12: 175278.03 | N12: 102630.69 | O12: 10366.173 | P12: 296976.22 | Q12: 9343.6419 | R12: 190649.26 | S12: 116897.08 | T12: 14033.036 | U12: 330923.02 | V12: 10782.581 | W12: 214095.16 | X12: 166662.65 | Y12: 12252.147 | Z12: 403792.54 | AA12: 15940.526 | AB12: 165135.79 | AC12: 169967.27 | AD12: 14216.061 | AE12: 365259.64 | AF12: 18302.724 | AG12: 245093.76 | AH12: 221319.19 | AI12: 7599.7974 | AJ12: 492315.47 | AK12: 33400.85 | AL12: 267171.7 | AM12: 256489.49 | AN12: 1259.8275 | AO12: 558321.87 | AP12: 54019.408 | AQ12: 374305.74 | AR12: 292044.82 | AS12: -2179.3625 | AT12: 718190.61 | AU12: 61190.723 | AV12: 379755.26 | AW12: 391434.79 | AX12: -869.4338 | AY12: 831511.34 | AZ12: 88707.7 | BA12: 417856.32 | BB12: 524075.95 | BC12: 14144.452 | BD12: 1044784.4
A13: Huambo | B13: 130868.34 | C13: 141760.18 | D13: 285604.36 | E13: 329.55237 | F13: 558562.42 | G13: 166903.72 | H13: 151339.54 | I13: 439750.53 | J13: 677.71003 | K13: 758671.5 | L13: 209830.13 | M13: 188761.4 | N13: 407526.61 | O13: 879.82234 | P13: 806997.96 | Q13: 236959.71 | R13: 185558.44 | S13: 477105.85 | T13: 1191.045 | U13: 900815.04 | V13: 266454.26 | W13: 190565.82 | X13: 645896.37 | Y13: 1039.8933 | Z13: 1103956.3 | AA13: 357807.93 | AB13: 256792.13 | AC13: 666342.32 | AD13: 1206.5792 | AE13: 1282149 | AF13: 547393.43 | AG13: 240446.9 | AH13: 889132.43 | AI13: 1154.494 | AJ13: 1678127.3 | AK13: 766656.11 | AL13: 292348.94 | AM13: 1101146.3 | AN13: 147.89099 | AO13: 2160299.2 | AP13: 937577.2 | AQ13: 258174.83 | AR13: 1690349.9 | AS13: -98.001453 | AT13: 2886003.9 | AU13: 1373618.2 | AV13: 299430.37 | AW13: 1894654.5 | AX13: -43.371253 | AY13: 3567659.7 | AZ13: 1955033.4 | BA13: 351618.03 | BB13: 2410413.3 | BC13: 909.35391 | BD13: 4717974
A14: Huíla | B14: 87348.514 | C14: 127073.27 | D14: 260881.96 | E14: 1148.8531 | F14: 476452.6 | G14: 111445.94 | H14: 161771.78 | I14: 312770.14 | J14: 2362.5661 | K14: 588350.43 | L14: 142182.43 | M14: 199519.71 | N14: 378052.38 | O14: 3067.1501 | P14: 722821.67 | Q14: 155659.01 | R14: 191270.8 | S14: 443343.11 | T14: 4152.1041 | U14: 794425.02 | V14: 178063.09 | W14: 301024.1 | X14: 518952.86 | Y14: 3625.1736 | Z14: 1001665.2 | AA14: 253026.6 | AB14: 241455.34 | AC14: 608742.14 | AD14: 4206.2577 | AE14: 1107430.3 | AF14: 326272.47 | AG14: 223288.61 | AH14: 818927.15 | AI14: 3973.0291 | AJ14: 1372461.3 | AK14: 538543.63 | AL14: 280603.79 | AM14: 1123995.4 | AN14: 512.84407 | AO14: 1943655.7 | AP14: 777132.46 | AQ14: 285102.46 | AR14: 1415913.9 | AS14: -399.8713 | AT14: 2477749 | AU14: 969711.76 | AV14: 482505.62 | AW14: 1817306.9 | AX14: -135.68191 | AY14: 3269388.6 | AZ14: 1444897.6 | BA14: 565570.8 | BB14: 2120819.6 | BC14: 3174.7381 | BD14: 4134462.7
A15: Luanda | B15: 124216.88 | C15: 1105510.7 | D15: 4275905.3 | E15: 229565.36 | F15: 5735198.3 | G15: 158858.79 | H15: 1401993.6 | I15: 4759505.4 | J15: 472091.12 | K15: 6792448.9 | L15: 194479.87 | M15: 1655875.6 | N15: 6002835.9 | O15: 612882.05 | P15: 8466073.4 | Q15: 205236.98 | R15: 2002973.1 | S15: 6951941.9 | T15: 829679.01 | U15: 9989831 | V15: 204660.89 | W15: 2207477 | X15: 8211450.3 | Y15: 724387.05 | Z15: 11347975 | AA15: 254651.29 | AB15: 2387371.7 | AC15: 9012081.4 | AD15: 840500.05 | AE15: 12494604 | AF15: 519300.18 | AG15: 3104684.3 | AH15: 11622788 | AI15: 533119.84 | AJ15: 15779892 | AK15: 603468.88 | AL15: 4508746.3 | AM15: 15259206 | AN15: 84548.992 | AO15: 20455970 | AP15: 826474.74 | AQ15: 5747788.5 | AR15: 17768498 | AS15: -119377.63 | AT15: 24223383 | AU15: 1145076.6 | AV15: 7146622.9 | AW15: 24040681 | AX15: -42955.421 | AY15: 32289425 | AZ15: 1487280.2 | BA15: 8844315.8 | BB15: 29695838 | BC15: 782821.44 | BD15: 40810255
A16: Lunda Norte | B16: 95528.271 | C16: 131931.23 | D16: 147120.33 | E16: 63.599912 | F16: 374643.43 | G16: 121490.57 | H16: 172222.85 | I16: 179371.03 | J16: 130.79044 | K16: 473215.24 | L16: 153501.67 | M16: 182870.11 | N16: 225095.37 | O16: 169.79585 | P16: 561636.94 | Q16: 173052.36 | R16: 223566.41 | S16: 269257.33 | T16: 229.85834 | U16: 666105.97 | V16: 192242.46 | W16: 238233.7 | X16: 304808.76 | Y16: 200.68774 | Z16: 735485.62 | AA16: 265643.35 | AB16: 218195.16 | AC16: 392236.49 | AD16: 232.85625 | AE16: 876307.85 | AF16: 397848.2 | AG16: 249264.7 | AH16: 588628.52 | AI16: 195.2187 | AJ16: 1235936.6 | AK16: 533268.25 | AL16: 276429.09 | AM16: 688657.27 | AN16: 21.611607 | AO16: 1498376.2 | AP16: 759205.18 | AQ16: 321054.11 | AR16: 684917.95 | AS16: -29.542398 | AT16: 1765147.7 | AU16: 1019184.6 | AV16: 340492.54 | AW16: 939046.23 | AX16: -10.281565 | AY16: 2298713 | AZ16: 1494854.3 | BA16: 360310.59 | BB16: 1336194.5 | BC16: 193.06892 | BD16: 3191552.5
... A23: ANGOLA | B23: 2159875.9 | C23: 5832104.4 | D23: 7568677.7 | E23: 246659.42 | F23: 15807317 | G23: 2755506.8 | H23: 7056538.6 | I23: 8742254.4 | J23: 507244.3 | K23: 19061544 | L23: 3463490.9 | M23: 8640379.7 | N23: 10782849 | O23: 658518.9 | P23: 23545238 | Q23: 3851649.9 | R23: 11940943 | S23: 12509729 | T23: 891459.15 | U23: 29193781 | V23: 4279721.3 | W23: 14647845 | X23: 15029141 | Y23: 778326.86 | Z23: 34735035 | AA23: 5778526.1 | AB23: 14202950 | AC23: 17359085 | AD23: 903085.95 | AE23: 38243647 | AF23: 8823858.8 | AG23: 20442415 | AH23: 22582358 | AI23: 575117.24 | AJ23: 52423748 | AK23: 12454215 | AL23: 23041326 | AM23: 28511344 | AN23: 90592.039 | AO23: 64097477 | AP23: 16204708 | AQ23: 27668419 | AR23: 33754615 | AS23: -127874.61 | AT23: 77499868 | AU23: 22417168 | AV23: 35243355 | AW23: 46396806 | AX23: -46239.892 | AY23: 1.0401109e+08 | AZ23: 32625275 | BA23: 35181731 | BB23: 59654789 | BC23: 840227.21 | BD23: 1.2830202e+08

Sheet Q7
A2: Quadro 7- Participação dos principais sectores de actividades no VAB por província em 2025* (%)
A4: Províncias | B4: 2015 | G4: 2016 | L4: 2017 | Q4: 2018 | V4: 2019 | AA4: 2020 | AF4: 2021 | AK4: 2022 | AP4: 2023 | AU4: 2024 | AZ4: 2025
B5: Agropecuária | C5: Indústria | D5: Serviços | E5: Impostos sobre os Produtos | F5: Produto Interno Bruto | G5: Agropecuária | H5: Indústria | I5: Serviços | J5: Impostos sobre os Produtos | K5: Produto Interno Bruto | L5: Agropecuária | M5: Indústria | N5: Serviços | O5: Impostos sobre os Produtos | P5: Produto Interno Bruto | Q5: Agropecuária | R5: Indústria | S5: Serviços | T5: Impostos sobre os Produtos | U5: Produto Interno Bruto | V5: Agropecuária | W5: Indústria | X5: Serviços | Y5: Impostos sobre os Produtos | Z5: Produto Interno Bruto | AA5: Agropecuária | AB5: Indústria | AC5: Serviços | AD5: Impostos sobre os Produtos | AE5: Produto Interno Bruto | AF5: Agropecuária | AG5: Indústria | AH5: Serviços | AI5: Impostos sobre os Produtos | AJ5: Produto Interno Bruto | AK5: Agropecuária | AL5: Indústria | AM5: Serviços | AN5: Impostos sobre os Produtos | AO5: Produto Interno Bruto | AP5: Agropecuária | AQ5: Indústria | AR5: Serviços | AS5: Impostos sobre os Produtos | AT5: Produto Interno Bruto | AU5: Agropecuária | AV5: Indústria | AW5: Serviços | AX5: Impostos sobre os Produtos | AY5: Produto Interno Bruto | AZ5: Agropecuária | BA5: Indústria | BB5: Serviços | BC5: Impostos sobre os Produtos | BD5: Produto Interno Bruto
A6: Bengo | B6: 4.4847162 | C6: 1.8977196 | D6: 1.2596165 | E6: 0.16884219 | F6: 1.9186941 | G6: 4.48493 | H6: 1.8697323 | I6: 1.2636074 | J6: 0.16884219 | K6: 1.9245301 | L6: 4.4942532 | M6: 2.0144029 | N6: 1.3093307 | O6: 0.16884219 | P6: 2.0046733 | Q6: 4.4471605 | R6: 1.44899 | S6: 1.2988817 | T6: 0.16884219 | U6: 1.7411375 | V6: 4.4303489 | W6: 1.0877687 | X6: 1.2708853 | Y6: 0.16884219 | Z6: 1.5582496 | AA6: 4.4782826 | AB6: 1.628507 | AC6: 1.3750029 | AD6: 0.16884219 | AE6: 1.9095655 | AF6: 4.3738178 | AG6: 0.98528896 | AH6: 1.5800395 | AI6: 0.26263465 | AJ6: 1.8039095 | AK6: 4.4726975 | AL6: 0.89498261 | AM6: 1.4934453 | AN6: 0.14668137 | AO6: 1.8552827 | AP6: 4.7174749 | AQ6: 1.2260685 | AR6: 1.5281726 | AS6: 0.20815869 | AT6: 2.0893577 | AU6: 4.5922671 | AV6: 1.5824514 | AW6: 1.4274876 | AX6: 0.057894056 | AY6: 2.1626993 | AZ6: 4.3904482 | BA6: 1.3044187 | BB6: 1.7549565 | BC6: 0.131512 | BD6: 2.2909487
A7: Benguela | B7: 7.9546557 | C7: 3.6624213 | D7: 6.9588947 | E7: 2.6441789 | F7: 5.8113931 | G7: 7.9848315 | H7: 4.2370561 | I7: 7.2527507 | J7: 2.6441789 | K7: 6.119538 | L7: 7.9476865 | M7: 3.9341394 | N7: 6.9017375 | O7: 2.6441789 | P7: 5.8475022 | Q7: 7.7048216 | R7: 2.3833385 | S7: 6.8471747 | T7: 2.6441789 | U7: 5.006171 | V7: 7.6246808 | W7: 3.0936365 | X7: 6.761006 | Y7: 2.6441789 | Z7: 5.2286335 | AA7: 7.4856696 | AB7: 3.1075216 | AC7: 6.8615323 | AD7: 2.6441789 | AE7: 5.4620825 | AF7: 7.5387975 | AG7: 3.0589958 | AH7: 6.3255025 | AI7: 2.8255741 | AJ7: 5.2175655 | AK7: 8.1390185 | AL7: 4.0553385 | AM7: 7.0250428 | AN7: 2.4208864 | AO7: 6.1674531 | AP7: 7.873932 | AQ7: 3.5041347 | AR7: 7.0792298 | AS7: 2.3192482 | AT7: 5.9768971 | AU7: 7.1301932 | AV7: 3.6502843 | AW7: 10.667068 | AX7: 3.011007 | AY7: 7.5305976 | AZ7: 7.0781392 | BA7: 4.2940978 | BB7: 10.739552 | BC7: 2.6200568 | BD7: 7.9879272
A8: Bié | B8: 6.3459656 | C8: 1.3327839 | D8: 2.2185633 | E8: 0.029672632 | F8: 2.4215584 | G8: 6.340304 | H8: 1.4674825 | I8: 2.3807457 | J8: 0.029672632 | K8: 2.5524812 | L8: 6.3598087 | M8: 1.3644931 | N8: 2.2219649 | O8: 0.029672632 | P8: 2.4546589 | Q8: 6.4318943 | R8: 0.97354375 | S8: 2.3294905 | T8: 0.029672632 | U8: 2.2458955 | V8: 6.5053235 | W8: 1.3616036 | X8: 2.4993555 | Y8: 0.029672632 | Z8: 2.4578007 | AA8: 6.5549871 | AB8: 0.88185975 | AC8: 2.0908593 | AD8: 0.029672632 | AE8: 2.2677067 | AF8: 6.4079242 | AG8: 0.58494354 | AH8: 2.7811544 | AI8: 0.028581 | AJ8: 2.5050047 | AK8: 6.4217957 | AL8: 0.57095221 | AM8: 2.6802555 | AN8: 0.057207438 | AO8: 2.6452958 | AP8: 6.3801017 | AQ8: 0.52137144 | AR8: 2.6941391 | AS8: 0.019070575 | AT8: 2.6935581 | AU8: 6.4912498 | AV8: 0.54318178 | AW8: 2.8346115 | AX8: 0.013831515 | AY8: 2.8475355 | AZ8: 6.2876796 | BA8: 0.56392154 | BB8: 2.7543827 | BC8: 0.02795572 | BD8: 3.0343452
A9: Cabinda | B9: 3.3251771 | C9: 12.397842 | D9: 3.4290916 | E9: 0.73706332 | F9: 6.6819036 | G9: 3.3323206 | H9: 11.800648 | I9: 3.3436564 | J9: 0.73706332 | K9: 6.4034124 | L9: 3.346587 | M9: 11.694491 | N9: 3.5126085 | O9: 0.73706332 | P9: 6.4130596 | Q9: 3.3274384 | R9: 13.560522 | S9: 3.0957736 | T9: 0.73706332 | U9: 7.3346408 | V9: 3.4083859 | W9: 12.996348 | X9: 2.7361762 | Y9: 0.73706332 | Z9: 7.1009427 | AA9: 3.4385553 | AB9: 11.255778 | AC9: 4.8669716 | AD9: 0.73706332 | AE9: 6.9262966 | AF9: 3.1905978 | AG9: 12.440347 | AH9: 2.9256427 | AI9: 0.64801739 | AJ9: 6.6554705 | AK9: 3.5630562 | AL9: 11.264257 | AM9: 2.4329124 | AN9: 0.60261294 | AO9: 5.8245458 | AP9: 3.4264613 | AQ9: 10.514638 | AR9: 2.308934 | AS9: 0.81590508 | AT9: 5.4746037 | AU9: 3.3419002 | AV9: 9.5699347 | AW9: 2.3112328 | AX9: 0.88171788 | AY9: 4.9935598 | AZ9: 3.4345059 | BA9: 8.3392489 | BB9: 2.3236458 | BC9: 0.78054993 | BD9: 4.2455554
A10: Cuando Cubango | B10: 0.60765684 | C10: 1.6056969 | D10: 0.73624314 | E10: 0.033339096 | F10: 1.0284899 | G10: 0.60653799 | H10: 1.6886271 | I10: 0.69819004 | J10: 0.033339096 | K10: 1.0339061 | L10: 0.60986269 | M10: 1.6377954 | N10: 0.74722584 | O10: 0.033339096 | P10: 1.0338653 | Q10: 0.61562454 | R10: 1.2198425 | S10: 0.67050892 | T10: 0.033339096 | U10: 0.86850161 | V10: 0.62061554 | W10: 1.174246 | X10: 0.79414054 | Y10: 0.033339096 | Z10: 0.91600411 | AA10: 0.63326647 | AB10: 0.89665833 | AC10: 0.67757512 | AD10: 0.033339096 | AE10: 0.73703045 | AF10: 0.60983448 | AG10: 0.80827552 | AH10: 0.84700394 | AI10: 0.022516835 | AJ10: 0.782937 | AK10: 0.60653719 | AL10: 0.76965715 | AM10: 0.8079364 | AN10: 0.040498694 | AO10: 0.75395928 | AP10: 0.63965173 | AQ10: 0.84966542 | AR10: 0.69145275 | AS10: 0.047121755 | AT10: 0.73816854 | AU10: 0.62667002 | AV10: 0.5443144 | AW10: 0.64332777 | AX10: 0.023219099 | AY10: 0.60646335 | AZ10: 0.57256572 | BA10: 0.53384248 | BB10: 0.65279236 | BC10: 0.03583512 | BD10: 0.59573431
A11: Cuanza Norte | B11: 4.4049167 | C11: 1.8186826 | D11: 1.9073833 | E11: 0.058493133 | F11: 2.1870642 | G11: 4.4009451 | H11: 2.006051 | I11: 1.9577868 | J11: 0.058493133 | K11: 2.2782914 | L11: 4.4213333 | M11: 1.9682672 | N11: 2.0451966 | O11: 0.058493133 | P11: 2.3109296 | Q11: 4.4573944 | R11: 1.3585288 | S11: 2.0934991 | T11: 0.058493133 | U11: 2.0426162 | V11: 4.5148925 | W11: 1.391128 | X11: 2.0474751 | Y11: 0.058493133 | Z11: 2.0301355 | AA11: 4.576961 | AB11: 1.059909 | AC11: 2.2099205 | AD11: 0.058493133 | AE11: 2.089679 | AF11: 4.3999329 | AG11: 0.87319937 | AH11: 2.5204663 | AI11: 0.065571245 | AJ11: 2.1675381 | AK11: 4.4773642 | AL11: 0.75322487 | AM11: 2.3422428 | AN11: 0.088010884 | AO11: 2.182704 | AP11: 4.5378854 | AQ11: 1.0098768 | AR11: 2.5286325 | AS11: 0.044979594 | AT11: 2.4106373 | AU11: 4.533343 | AV11: 0.86391193 | AW11: 2.2469556 | AX11: 0.03541081 | AY11: 2.2720827 | AZ11: 4.5208796 | BA11: 1.0049405 | BB11: 2.2827078 | BC11: 0.053568845 | BD11: 2.4868661
A12: Cuanza Sul | B12: 11.578602 | C12: 2.7954897 | D12: 3.7475377 | E12: 0.10122904 | F12: 4.4094012 | G12: 11.586635 | H12: 3.1782713 | I12: 3.8353064 | J12: 0.10122904 | K12: 4.6132264 | L12: 11.571999 | M12: 3.4714371 | N12: 3.9028154 | O12: 0.10122904 | P12: 4.7663215 | Q12: 11.650365 | R12: 2.3277619 | S12: 3.9680165 | T12: 0.10122904 | U12: 4.1926001 | V12: 11.738355 | W12: 2.0217602 | X12: 4.0915725 | Y12: 0.10122904 | Z12: 4.0714779 | AA12: 11.597224 | AB12: 3.4015415 | AC12: 4.8733854 | AD12: 0.10122904 | AE12: 5.2300377 | AF12: 11.681356 | AG12: 2.8752081 | AH12: 4.3866931 | AI12: 0.11980193 | AJ12: 4.9783087 | AK12: 11.79375 | AL12: 1.113202 | AM12: 4.0762749 | AN12: 0.10919115 | AO12: 4.5050371 | AP12: 10.968006 | AQ12: 1.2010772 | AR12: 3.8179147 | AS12: 0.11091354 | AT12: 4.3848243 | AU12: 11.483578 | AV12: 1.3270972 | AW12: 3.3920023 | AX12: 0.065009538 | AY12: 4.4377549 | AZ12: 10.669342 | BA12: 1.2625873 | BB12: 3.7732795 | BC12: 0.092393354 | BD12: 4.8142816
A13: Cunene | B13: 0.24509118 | C13: 2.0216373 | D13: 1.0275531 | E13: 1.5741648 | F13: 1.2959357 | G13: 0.24503906 | H13: 2.0777295 | I13: 1.027831 | J13: 1.5741648 | K13: 1.3178802 | L13: 0.25123023 | M13: 2.0285917 | N13: 0.95179567 | O13: 1.5741648 | P13: 1.2613006 | Q13: 0.24258804 | R13: 1.5966013 | S13: 0.93444933 | T13: 1.5741648 | U13: 1.1335394 | V13: 0.25194586 | W13: 1.4616154 | X13: 1.10893 | Y13: 1.5741648 | Z13: 1.1624936 | AA13: 0.27585799 | AB13: 1.1626865 | AC13: 0.97912574 | AD13: 1.5741648 | AE13: 0.9550858 | AF13: 0.20742313 | AG13: 1.1989472 | AH13: 0.9800535 | AI13: 1.3214345 | AJ13: 0.93910773 | AK13: 0.26818913 | AL13: 1.1595326 | AM13: 0.89960505 | AN13: 1.3906603 | AO13: 0.87105123 | AP13: 0.33335625 | AQ13: 1.3528266 | AR13: 0.8651997 | AS13: 1.7042966 | AT13: 0.92669914 | AU13: 0.27296367 | AV13: 1.077523 | AW13: 0.84366754 | AX13: 1.8802678 | AY13: 0.7994449 | AZ13: 0.2718987 | BA13: 1.1877083 | BB13: 0.87851446 | BC13: 1.683408 | BD13: 0.81431641
A14: Huambo | B14: 6.0590675 | C14: 2.4306865 | D14: 3.773504 | E14: 0.13360624 | F14: 3.5335687 | G14: 6.0570972 | H14: 2.144671 | I14: 5.0301731 | J14: 0.13360624 | K14: 3.9801157 | L14: 6.0583422 | M14: 2.1846425 | N14: 3.7793964 | O14: 0.13360624 | P14: 3.4274359 | Q14: 6.1521611 | R14: 1.553968 | S14: 3.8138785 | T14: 0.13360624 | U14: 3.0856402 | V14: 6.2259722 | W14: 1.3009819 | X14: 4.2976266 | Y14: 0.13360624 | Z14: 3.1782215 | AA14: 6.1920276 | AB14: 1.8080197 | AC14: 3.8385797 | AD14: 0.13360624 | AE14: 3.3525802 | AF14: 6.2035607 | AG14: 1.1762158 | AH14: 3.9372879 | AI14: 0.20074063 | AJ14: 3.2010822 | AK14: 6.1557964 | AL14: 1.2688026 | AM14: 3.8621339 | AN14: 0.16324943 | AO14: 3.3703343 | AP14: 5.785832 | AQ14: 0.93310292 | AR14: 5.0077595 | AS14: 0.076638713 | AT14: 3.7238824 | AU14: 6.127528 | AV14: 0.84960803 | AW14: 4.0835883 | AX14: 0.093796182 | AY14: 3.4300764 | AZ14: 5.992389 | BA14: 0.99943356 | BB14: 4.0406031 | BC14: 0.10822714 | BD14: 3.6772406
A15: Huíla | B15: 4.0441451 | C15: 2.178858 | D15: 3.4468631 | E15: 0.46576494 | F15: 3.0141269 | G15: 4.0444809 | H15: 2.292509 | I15: 3.5776828 | J15: 0.46576494 | K15: 3.0865833 | L15: 4.105177 | M15: 2.3091544 | N15: 3.5060528 | O15: 0.46576494 | P15: 3.0699271 | Q15: 4.0413592 | R15: 1.6018064 | S15: 3.5439866 | T15: 0.46576494 | U15: 2.7212132 | V15: 4.1606235 | W15: 2.0550742 | X15: 3.4529775 | Y15: 0.46576494 | Z15: 2.8837317 | AA15: 4.3787394 | AB15: 1.7000366 | AC15: 3.506764 | AD15: 0.46576494 | AE15: 2.8957237 | AF15: 3.6976167 | AG15: 1.092281 | AH15: 3.6264024 | AI15: 0.69082073 | AJ15: 2.6180144 | AK15: 4.3241877 | AL15: 1.2178283 | AM15: 3.9422744 | AN15: 0.5661028 | AO15: 3.0323435 | AP15: 4.7957201 | AQ15: 1.0304255 | AR15: 4.194727 | AS15: 0.31270579 | AT15: 3.1971009 | AU15: 4.3257551 | AV15: 1.3690684 | AW15: 3.9168794 | AX15: 0.29343043 | AY15: 3.1433078 | AZ15: 4.4287675 | BA15: 1.6075696 | BB15: 3.555154 | BC15: 0.37784281 | BD15: 3.2224455
A16: Luanda | B16: 5.7511122 | C16: 18.955605 | D16: 56.494747 | E16: 93.069774 | F16: 36.28192 | G16: 5.7651388 | H16: 19.868007 | I16: 54.442541 | J16: 93.069774 | K16: 35.634306 | L16: 5.6151402 | M16: 19.164384 | N16: 55.670221 | O16: 93.069774 | P16: 35.956626 | Q16: 5.3285472 | R16: 16.773994 | S16: 55.572284 | T16: 93.069774 | U16: 34.219038 | V16: 4.7821078 | W16: 15.070319 | X16: 54.636856 | Y16: 93.069774 | Z16: 32.670113 | AA16: 4.4068553 | AB16: 16.808985 | AC16: 51.915648 | AD16: 93.069774 | AE16: 32.671059 | AF16: 5.8851823 | AG16: 15.187464 | AH16: 51.468444 | AI16: 92.697594 | AJ16: 30.100656 | AK16: 4.8454992 | AL16: 19.568085 | AM16: 53.519768 | AN16: 93.329385 | AO16: 31.913845 | AP16: 5.1002136 | AQ16: 20.773823 | AR16: 52.640203 | AS16: 93.355226 | AT16: 31.256032 | AU16: 5.1080345 | AV16: 20.27793 | AW16: 51.81538 | AX16: 92.89689 | AY16: 31.044215 | AZ16: 4.5586747 | BA16: 25.138945 | BB16: 49.77947 | BC16: 93.167828 | BD16: 31.80796
A17: Lunda Norte | B17: 4.4228593 | C17: 2.2621547 | D17: 1.943805 | E17: 0.025784506 | F17: 2.3700633 | G17: 4.40901 | H17: 2.4406137 | I17: 2.0517709 | J17: 0.025784506 | K17: 2.4825651 | L17: 4.4319929 | M17: 2.1164592 | N17: 2.0875315 | O17: 0.025784506 | P17: 2.3853525 | Q17: 4.4929411 | R17: 1.8722676 | S17: 2.1523835 | T17: 0.025784506 | U17: 2.2816708 | V17: 4.4919389 | W17: 1.6264078 | X17: 2.0281183 | Y17: 0.025784506 | Z17: 2.1174172 | AA17: 4.5970779 | AB17: 1.5362665 | AC17: 2.2595459 | AD17: 0.025784506 | AE17: 2.2913815 | AF17: 4.508778 | AG17: 1.2193506 | AH17: 2.6065858 | AI17: 0.033944157 | AJ17: 2.3575892 | AK17: 4.2818295 | AL17: 1.19971 | AM17: 2.4153798 | AN17: 0.023855967 | AO17: 2.3376524 | AP17: 4.68509 | AQ17: 1.160363 | AR17: 2.0291091 | AS17: 0.02310263 | AT17: 2.2776138 | AU17: 4.5464466 | AV17: 0.96611843 | AW17: 2.0239459 | AX17: 0.02223527 | AY17: 2.2100654 | AZ17: 4.5818904 | BA17: 1.0241412 | BB17: 2.239878 | BC17: 0.02297818 | BD17: 2.4875309
... A24: ANGOLA | B24: 100 | C24: 100 | D24: 100 | E24: 100 | F24: 100 | G24: 100 | H24: 100 | I24: 100 | J24: 100 | K24: 100 | L24: 100 | M24: 100 | N24: 100 | O24: 100 | P24: 100 | Q24: 100 | R24: 100 | S24: 100 | T24: 100 | U24: 100 | V24: 100 | W24: 100 | X24: 100 | Y24: 100 | Z24: 100 | AA24: 100 | AB24: 100 | AC24: 100 | AD24: 100 | AE24: 100 | AF24: 100 | AG24: 100 | AH24: 100 | AI24: 100 | AJ24: 100 | AK24: 100 | AL24: 100 | AM24: 100 | AN24: 100 | AO24: 100 | AP24: 100 | AQ24: 100 | AR24: 100 | AS24: 100 | AT24: 100 | AU24: 100 | AV24: 100 | AW24: 100 | AX24: 100 | AY24: 100 | AZ24: 100 | BA24: 100 | BB24: 100 | BC24: 100 | BD24: 100

Sheet Q8
A2: Quadro 8 - PIB por província, variações percentuais de volume 2015 - 2025*
A3: Províncias | B3: 2016 | C3: 2017 | D3: 2018 | E3: 2019 | F3: 2020 | G3: 2021 | H3: 2022 | I3: 2023 | J3: 2024 | K3: 2025
A4: Bengo | B4: -2.2683538 | C4: 4.8464722 | D4: -1.4307458 | E4: -7.1690567 | F4: 12.18673 | G4: 0.089531955 | H4: -0.58908087 | I4: 14.056718 | J4: 6.5099086 | K4: 3.1828774
A5: Benguela | B5: 4.9620449 | C5: -2.4060735 | D5: -5.2292646 | E5: 6.8193598 | F5: -4.3659479 | G5: 3.5525619 | H5: 15.908346 | I5: -1.0945294 | J5: 33.138034 | K5: 4.0063378
A6: Bié | B6: 1.6474211 | C6: -3.0243305 | D6: 1.2024875 | E6: 13.06137 | F6: -17.078023 | G6: 17.15201 | H6: 0.9762787 | I6: 1.7312521 | J6: 8.7334469 | K6: 0.6194281
A7: Cabinda | B7: -1.8497366 | C7: -4.2779162 | D7: -6.5306452 | E7: -7.5699977 | F7: -0.96024402 | G7: -17.155268 | H7: -1.9429753 | I7: -5.6679611 | J7: -1.097879 | K7: -4.7801127
A8: Cuando Cubango | B8: -1.5156005 | C8: 4.1980968 | D8: -1.1563802 | E8: 9.9700695 | F8: -22.85515 | G8: 20.696453 | H8: -0.85614819 | I8: 2.8697669 | J8: -12.824408 | K8: 0.61940509
A9: Cuanza Norte | B9: 0.7914266 | C9: 1.0606181 | D9: -1.6344562 | E9: 2.3763791 | F9: -6.8841619 | G9: 10.643558 | H9: -2.9100149 | I9: 11.638973 | J9: -3.1392706 | K9: 4.6579292
A10: Cuanza Sul | B10: 1.6599602 | C10: 3.6176482 | D10: -2.9624067 | E10: 0.54357995 | F10: 16.256324 | G10: 0.57169203 | H10: -13.525249 | I10: -2.445723 | J10: 4.7690498 | K10: 2.2972228
A11: Cunene | B11: 0.057665222 | C11: 0.28193503 | D11: 4.8977874 | E11: 6.1344601 | F11: -20.552079 | G11: 13.838645 | H11: -3.3365133 | I11: 14.189488 | J11: -5.0930778 | K11: 9.096408
A12: Huambo | B12: 12.533027 | C12: -12.933236 | D12: -0.51604045 | E12: 7.2039472 | F12: -3.6638427 | G12: 2.6470333 | H12: 2.8156967 | I12: 12.529588 | J12: -4.8861838 | K12: 3.0178639
A13: Huíla | B13: 0.60601902 | C13: 1.6763496 | D13: -1.1855652 | E13: 8.163578 | F13: -7.7300878 | G13: -1.0215935 | H13: 12.981119 | I13: 6.8734194 | J13: 2.5707603 | K13: 0.58572452
A14: Luanda | B14: -1.4928823 | C14: 3.5851262 | D14: 4.2161527 | E14: -3.8794985 | F14: -7.6831475 | G14: 3.201882 | H14: 7.2679237 | I14: 0.69788719 | J14: 3.6836985 | K14: 4.353773
... A22: ANGOLA | B22: -0.23307695 | C22: -0.16468866 | D22: -0.50669754 | E22: -1.0552341 | F22: -5.2734913 | G22: 1.0905837 | H22: 3.5574921 | I22: 1.3201659 | J22: 4.9526786 | K22: 3.1335354

Sheet Planilha2
B3: Rótulos de Coluna
A4: Rótulos de Linha | B4: Baixo Dinamismo | C4: Crescimento Baseado em Preços | D4: Crescimento com Pressão de Preços | E4: Crescimento Real Forte | F4: Total Geral
A5: Bengo
A6: Benguela
A7: Bié
A8: Cabinda
A9: Cuando Cubango
A10: Cuanza Norte
A11: Cuanza Sul
A12: Cunene
A13: Huambo
A14: Huíla
A15: Luanda
A16: Lunda Norte
... A23: Total Geral

Sheet Modelagem
B3: Quadro 1- Produto Interno Bruto (PIB) por Províncias, a preços correntes: 2020 - 2025 | G3: Quadro 3- PIB por Províncias a preços do ano anterior: 2020 - 2025 | K3: Quadro 4- PIB por província, variações percentuais de preços 2020 - 2025 | O3: Quadro 5- PIB per Capita por Províncias, a preços correntes: 2020 - 2025 | S3: Quadro 6- Produto Interno Bruto por Província e por sectores de actividades à preços correntes | AA3: Quadro 8 - PIB por província, variações percentuais de volume 2020 - 2025 | AN3: Base para cálculo do Crescimento Províncial, Desvio Padrão e Dinamismo do Crescimento
B4: Ano | C4: Coluna1 | D4: Províncias | E4: PIB | G4: Ano | H4: Províncias | I4: Preços do ano anterior | K4: Ano | L4: Províncias | M4: Valores percentuais do preço | O4: Ano | P4: Províncias | Q4: PIB per Capita | S4: Ano | T4: Províncias | U4: Agropecuária | V4: Indústria | W4: Serviços | X4: Impostos sobre os Produtos | Y4: Produto Interno Bruto | AA4: Ano | AB4: Províncias | AC4: variação Percentual dp Volume | AE4: Média dos percentuais do preço | AF4: =AVERAGE(Tabela25[Média do preço (%)]) -> 23.978924 | AN4: 2020 | AO4: 2021 | AP4: 2022 | AQ4: 2023 | AR4: 2024 | AS4: 2025
B5: 2020 | C5: Litoral | D5: Luanda | E5: 12494.604 | G5: 2020 | H5: Bengo | I5: 607.22027 | K5: 2020 | L5: Bengo | M5: 20.267307 | O5: 2025 | P5: Zaire | Q5: 25830.314 | S5: 2020 | T5: Bengo | U5: 258778.73 | V5: 231296.03 | W5: 238687.92 | X5: 1524.7901 | Y5: 730287.47 | AA5: 2020 | AB5: Bengo | AC5: 12.18673 | AE5: Média Percentual do Volume | AF5: =AVERAGE(Tabela25[Média do Volume (%)]) -> 1.9225228 | AN5: Quadro 8 - PIB por província, variações percentuais de volume 2015 - 2025*
B6: 2020 | C6: Litoral | D6: Zaire | E6: 6584.6422 | G6: 2020 | H6: Benguela | I6: 1736.8747 | K6: 2020 | L6: Benguela | M6: 20.267714 | O6: 2025 | P6: Cabinda | Q6: 5883.7647 | S6: 2020 | T6: Benguela | U6: 432561.37 | V6: 441359.74 | W6: 1191099.2 | X6: 23879.208 | Y6: 2088899.5 | AA6: 2020 | AB6: Benguela | AC6: -4.3659479 | AE6: Províncias | AF6: Média do preço (%) | AG6: Média do Volume (%) | AH6: Classificação | AJ6: Base para cálculo do Crescimento Total de 2025 | AN6: Províncias | AO6: 2020 | AP6: 2021 | AQ6: 2022 | AR6: 2023 | AS6: 2024 | AT6: 2025 | AU6: Crescimento | AV6: Desvio Padrão | AW6: Classificação | AX6: Dinamismo
B7: 2020 | C7: Litoral | D7: Benguela | E7: 2088.8995 | G7: 2020 | H7: Bié | I7: 707.91978 | K7: 2020 | L7: Bié | M7: 22.507349 | O7: 2025 | P7: Cuanza Norte | Q7: 4723.7781 | S7: 2020 | T7: Bié | U7: 378781.64 | V7: 125250.1 | W7: 362954.05 | X7: 267.96937 | Y7: 867253.76 | AA7: 2020 | AB7: Bié | AC7: -17.078023 | AE7: Bengo | AF7: =AVERAGEIF(Quadro_4[Províncias],AE7, Quadro_4[Valores percentuais do preço]) -> 25.43168 | AG7: =AVERAGEIF(Quadro_8[Províncias], AE7, Quadro_8[variação Percentual dp Volume]) -> 5.9061142 | AH7: Crescimento com Pressão de Preços | AJ7: Província | AK7: PIB 2024 | AL7: Crescimento 2025 | AN7: Bengo | AO7: 12.18673 | AP7: 0.089531955 | AQ7: -0.58908087 | AR7: 14.056718 | AS7: 6.5099086 | AT7: 3.1828774 | AU7: =(1+Quadro8[[#This Row],[2021]]/100)*(1+Quadro8[[#This Row],[2022]]/100)*(1+Quadro8[[#This Row],[2023]]/100)*(1+Quadro8[[#This Row],[2024]]/100)*(1+Quadro8[[#This Row],[2025]]/100)-1 -> 0.24721482 | AV7: =_xlfn.STDEV.P(Quadro8[[#This Row],[2020]:[2025]]) -> 5.6225625 | AW7: =IF(Quadro8[[#This Row],[Desvio Padrão]]<=5.86, "Muito Consistente", IF(AND(AV7>5.86, AV7<=7.66), "Consistente", IF(AND(AV7>7.66, AV7<=9.98), "Instável", "Muito instável"))) -> Muito Consistente | AX7: =SLOPE(Quadro8[[#This Row],[2020]:[2025]], Modelagem!$AN$4:$AS$4) -> -0.31749527
B8: 2020 | C8: Interior | D8: Uige | E8: 2023.7259 | G8: 2020 | H8: Cabinda | I8: 2442.8304 | K8: 2020 | L8: Cabinda | M8: 8.4343987 | O8: 2025 | P8: Lunda Sul | Q8: 4060.7138 | S8: 2020 | T8: Cabinda | U8: 198697.82 | V8: 1598652.6 | W8: 844861.74 | X8: 6656.3153 | Y8: 2648868.4 | AA8: 2020 | AB8: Cabinda | AC8: -0.96024402 | AE8: Benguela | AF8: =AVERAGEIF(Quadro_4[Províncias],AE8, Quadro_4[Valores percentuais do preço]) -> 23.781992 | AG8: =AVERAGEIF(Quadro_8[Províncias], AE8, Quadro_8[variação Percentual dp Volume]) -> 8.5241338 | AH8: Crescimento Real Forte | AJ8: Luanda | AK8: 32289.425 | AL8: 4.353773 | AN8: Benguela | AO8: -4.3659479 | AP8: 3.5525619 | AQ8: 15.908346 | AR8: -1.0945294 | AS8: 33.138034 | AT8: 4.0063378 | AU8: =(1+Quadro8[[#This Row],[2021]]/100)*(1+Quadro8[[#This Row],[2022]]/100)*(1+Quadro8[[#This Row],[2023]]/100)*(1+Quadro8[[#This Row],[2024]]/100)*(1+Quadro8[[#This Row],[2025]]/100)-1 -> 0.64383346 | AV8: =_xlfn.STDEV.P(Quadro8[[#This Row],[2020]:[2025]]) -> 12.676557 | AW8: =IF(Quadro8[[#This Row],[Desvio Padrão]]<=5.86, "Muito Consistente", IF(AND(AV8>5.86, AV8<=7.66), "Consistente", IF(AND(AV8>7.66, AV8<=9.98), "Instável", "Muito instável"))) -> Muito instável | AX8: =SLOPE(Quadro8[[#This Row],[2020]:[2025]], Modelagem!$AN$4:$AS$4) -> 3.246142
B9: 2020 | C9: Litoral | D9: Cabinda | E9: 2648.8684 | G9: 2020 | H9: Cuando Cubango | I9: 245.45512 | K9: 2020 | L9: Cuando Cubango | M9: 14.834565 | O9: 2025 | P9: Malanje | Q9: 4586.961 | S9: 2020 | T9: Cuando Cubango | U9: 36593.469 | V9: 127351.93 | W9: 117620.84 | X9: 301.08069 | Y9: 281867.32 | AA9: 2020 | AB9: Cuando Cubango | AC9: -22.85515 | AE9: Bié | AF9: =AVERAGEIF(Quadro_4[Províncias],AE9, Quadro_4[Valores percentuais do preço]) -> 26.961593 | AG9: =AVERAGEIF(Quadro_8[Províncias], AE9, Quadro_8[variação Percentual dp Volume]) -> 2.0223988 | AH9: Crescimento com Pressão de Preços | AJ9: Zaire | AK9: 18417.765 | AL9: -0.18846023 | AN9: Bié | AO9: -17.078023 | AP9: 17.15201 | AQ9: 0.9762787 | AR9: 1.7312521 | AS9: 8.7334469 | AT9: 0.6194281 | AU9: =(1+Quadro8[[#This Row],[2021]]/100)*(1+Quadro8[[#This Row],[2022]]/100)*(1+Quadro8[[#This Row],[2023]]/100)*(1+Quadro8[[#This Row],[2024]]/100)*(1+Quadro8[[#This Row],[2025]]/100)-1 -> 0.31664439 | AV9: =_xlfn.STDEV.P(Quadro8[[#This Row],[2020]:[2025]]) -> 10.34341 | AW9: =IF(Quadro8[[#This Row],[Desvio Padrão]]<=5.86, "Muito Consistente", IF(AND(AV9>5.86, AV9<=7.66), "Consistente", IF(AND(AV9>7.66, AV9<=9.98), "Instável", "Muito instável"))) -> Muito instável | AX9: =SLOPE(Quadro8[[#This Row],[2020]:[2025]], Modelagem!$AN$4:$AS$4) -> 1.8281868
B10: 2020 | C10: Litoral | D10: Cuanza Sul | E10: 2000.1572 | G10: 2020 | H10: Cuanza Norte | I10: 656.62335 | K10: 2020 | L10: Cuanza Norte | M10: 21.708959 | O10: 2025 | P10: Luanda | Q10: 3908.3374 | S10: 2020 | T10: Cuanza Norte | U10: 264480.89 | V10: 150538.34 | W10: 383621.98 | X10: 528.24327 | Y10: 799169.45 | AA10: 2020 | AB10: Cuanza Norte | AC10: -6.8841619 | AE10: Cabinda | AF10: =AVERAGEIF(Quadro_4[Províncias],AE10, Quadro_4[Valores percentuais do preço]) -> 21.823529 | AG10: =AVERAGEIF(Quadro_8[Províncias], AE10, Quadro_8[variação Percentual dp Volume]) -> -5.2674067 | AH10: Baixo Dinamismo | AJ10: Benguela | AK10: 7832.6565 | AL10: 4.0063378 | AN10: Cabinda | AO10: -0.96024402 | AP10: -17.155268 | AQ10: -1.9429753 | AR10: -5.6679611 | AS10: -1.097879 | AT10: -4.7801127 | AU10: =(1+Quadro8[[#This Row],[2021]]/100)*(1+Quadro8[[#This Row],[2022]]/100)*(1+Quadro8[[#This Row],[2023]]/100)*(1+Quadro8[[#This Row],[2024]]/100)*(1+Quadro8[[#This Row],[2025]]/100)-1 -> -0.27833425 | AV10: =_xlfn.STDEV.P(Quadro8[[#This Row],[2020]:[2025]]) -> 5.6081431 | AW10: =IF(Quadro8[[#This Row],[Desvio Padrão]]<=5.86, "Muito Consistente", IF(AND(AV10>5.86, AV10<=7.66), "Consistente", IF(AND(AV10>7.66, AV10<=9.98), "Instável", "Muito instável"))) -> Muito Consistente | AX10: =SLOPE(Quadro8[[#This Row],[2020]:[2025]], Modelagem!$AN$4:$AS$4) -> 0.72422399
B11: 2020 | C11: Interior | D11: Malanje | E11: 1392.0194 | G11: 2020 | H11: Cuanza Sul | I11: 1644.131 | K11: 2020 | L11: Cuanza Sul | M11: 21.654369 | O11: 2025 | P11: Bengo | Q11: 4003.9188 | S11: 2020 | T11: Cuanza Sul | U11: 670148.64 | V11: 483119.23 | W11: 845975.11 | X11: 914.18524 | Y11: 2000157.2 | AA11: 2020 | AB11: Cuanza Sul | AC11: 16.256324 | AE11: Cuando Cubango | AF11: =AVERAGEIF(Quadro_4[Províncias],AE11, Quadro_4[Valores percentuais do preço]) -> 19.370774 | AG11: =AVERAGEIF(Quadro_8[Províncias], AE11, Quadro_8[variação Percentual dp Volume]) -> -2.0583469 | AH11: Baixo Dinamismo | AJ11: Uige | AK11: 6046.64 | AL11: 6.2803174 | AN11: Cuando Cubango | AO11: -22.85515 | AP11: 20.696453 | AQ11: -0.85614819 | AR11: 2.8697669 | AS11: -12.824408 | AT11: 0.61940509 | AU11: =(1+Quadro8[[#This Row],[2021]]/100)*(1+Quadro8[[#This Row],[2022]]/100)*(1+Quadro8[[#This Row],[2023]]/100)*(1+Quadro8[[#This Row],[2024]]/100)*(1+Quadro8[[#This Row],[2025]]/100)-1 -> 0.0797537 | AV11: =_xlfn.STDEV.P(Quadro8[[#This Row],[2020]:[2025]]) -> 13.534511 | AW11: =IF(Quadro8[[#This Row],[Desvio Padrão]]<=5.86, "Muito Consistente", IF(AND(AV11>5.86, AV11<=7.66), "Consistente", IF(AND(AV11>7.66, AV11<=9.98), "Instável", "Muito instável"))) -> Muito instável | AX11: =SLOPE(Quadro8[[#This Row],[2020]:[2025]], Modelagem!$AN$4:$AS$4) -> 0.58674599
B12: 2020 | C12: Interior | D12: Huambo | E12: 1282.149 | G12: 2020 | H12: Cunene | I12: 320.80478 | K12: 2020 | L12: Cunene | M12: 13.857295 | O12: 2025 | P12: Benguela | Q12: 3849.8326 | S12: 2020 | T12: Cunene | U12: 15940.526 | V12: 165135.79 | W12: 169967.27 | X12: 14216.061 | Y12: 365259.64 | AA12: 2020 | AB12: Cunene | AC12: -20.552079 | AE12: Cuanza Norte | AF12: =AVERAGEIF(Quadro_4[Províncias],AE12, Quadro_4[Valores percentuais do preço]) -> 26.040743 | AG12: =AVERAGEIF(Quadro_8[Províncias], AE12, Quadro_8[variação Percentual dp Volume]) -> 2.3345022 | AH12: Crescimento com Pressão de Preços | AJ12: Cabinda | AK12: 5193.8559 | AL12: -4.7801127 | AN12: Cuanza Norte | AO12: -6.8841619 | AP12: 10.643558 | AQ12: -2.9100149 | AR12: 11.638973 | AS12: -3.1392706 | AT12: 4.6579292 | AU12: =(1+Quadro8[[#This Row],[2021]]/100)*(1+Quadro8[[#This Row],[2022]]/100)*(1+Quadro8[[#This Row],[2023]]/100)*(1+Quadro8[[#This Row],[2024]]/100)*(1+Quadro8[[#This Row],[2025]]/100)-1 -> 0.21572759 | AV12: =_xlfn.STDEV.P(Quadro8[[#This Row],[2020]:[2025]]) -> 7.1117604 | AW12: =IF(Quadro8[[#This Row],[Desvio Padrão]]<=5.86, "Muito Consistente", IF(AND(AV12>5.86, AV12<=7.66), "Consistente", IF(AND(AV12>7.66, AV12<=9.98), "Instável", "Muito instável"))) -> Consistente | AX12: =SLOPE(Quadro8[[#This Row],[2020]:[2025]], Modelagem!$AN$4:$AS$4) -> 0.88317022
B13: 2020 | C13: Interior | D13: Huíla | E13: 1107.4303 | G13: 2020 | H13: Huambo | I13: 1063.5091 | K13: 2020 | L13: Huambo | M13: 20.558342 | O13: 2025 | P13: Uige | Q13: 4130.4286 | S13: 2020 | T13: Huambo | U13: 357807.93 | V13: 256792.13 | W13: 666342.32 | X13: 1206.5792 | Y13: 1282149 | AA13: 2020 | AB13: Huambo | AC13: -3.6638427 | AE13: Cuanza Sul | AF13: =AVERAGEIF(Quadro_4[Províncias],AE13, Quadro_4[Valores percentuais do preço]) -> 26.739507 | AG13: =AVERAGEIF(Quadro_8[Províncias], AE13, Quadro_8[variação Percentual dp Volume]) -> 1.3205529 | AH13: Crescimento Baseado em Preços | AJ13: Cuanza Sul | AK13: 4615.7572 | AL13: 2.2972228 | AN13: Cuanza Sul | AO13: 16.256324 | AP13: 0.57169203 | AQ13: -13.525249 | AR13: -2.445723 | AS13: 4.7690498 | AT13: 2.2972228 | AU13: =(1+Quadro8[[#This Row],[2021]]/100)*(1+Quadro8[[#This Row],[2022]]/100)*(1+Quadro8[[#This Row],[2023]]/100)*(1+Quadro8[[#This Row],[2024]]/100)*(1+Quadro8[[#This Row],[2025]]/100)-1 -> -0.090697799 | AV13: =_xlfn.STDEV.P(Quadro8[[#This Row],[2020]:[2025]]) -> 8.8606502 | AW13: =IF(Quadro8[[#This Row],[Desvio Padrão]]<=5.86, "Muito Consistente", IF(AND(AV13>5.86, AV13<=7.66), "Consistente", IF(AND(AV13>7.66, AV13<=9.98), "Instável", "Muito instável"))) -> Instável | AX13: =SLOPE(Quadro8[[#This Row],[2020]:[2025]], Modelagem!$AN$4:$AS$4) -> -1.317826
B14: 2020 | C14: Interior | D14: Lunda Sul | E14: 1316.3938 | G14: 2020 | H14: Huíla | I14: 924.23562 | K14: 2020 | L14: Huíla | M14: 19.821215 | O14: 2025 | P14: Moxico | Q14: 3693.8561 | S14: 2020 | T14: Huíla | U14: 253026.6 | V14: 241455.34 | W14: 608742.14 | X14: 4206.2577 | Y14: 1107430.3 | AA14: 2020 | AB14: Huíla | AC14: -7.7300878 | AE14: Cunene | AF14: =AVERAGEIF(Quadro_4[Províncias],AE14, Quadro_4[Valores percentuais do preço]) -> 16.565449 | AG14: =AVERAGEIF(Quadro_8[Províncias], AE14, Quadro_8[variação Percentual dp Volume]) -> 1.3571452 | AH14: Baixo Dinamismo | AJ14: Malanje | AK14: 4357.9844 | AL14: 5.9091393 | AN14: Cunene | AO14: -20.552079 | AP14: 13.838645 | AQ14: -3.3365133 | AR14: 14.189488 | AS14: -5.0930778 | AT14: 9.096408 | AU14: =(1+Quadro8[[#This Row],[2021]]/100)*(1+Quadro8[[#This Row],[2022]]/100)*(1+Quadro8[[#This Row],[2023]]/100)*(1+Quadro8[[#This Row],[2024]]/100)*(1+Quadro8[[#This Row],[2025]]/100)-1 -> 0.301028 | AV14: =_xlfn.STDEV.P(Quadro8[[#This Row],[2020]:[2025]]) -> 12.409694 | AW14: =IF(Quadro8[[#This Row],[Desvio Padrão]]<=5.86, "Muito Consistente", IF(AND(AV14>5.86, AV14<=7.66), "Consistente", IF(AND(AV14>7.66, AV14<=9.98), "Instável", "Muito instável"))) -> Muito instável | AX14: =SLOPE(Quadro8[[#This Row],[2020]:[2025]], Modelagem!$AN$4:$AS$4) -> 3.1135219
B15: 2020 | C15: Interior | D15: Bié | E15: 867.25376 | G15: 2020 | H15: Luanda | I15: 10476.094 | K15: 2020 | L15: Luanda | M15: 19.267782 | O15: 2025 | P15: Cuanza Sul | Q15: 2589.0379 | S15: 2020 | T15: Luanda | U15: 254651.29 | V15: 2387371.7 | W15: 9012081.4 | X15: 840500.05 | Y15: 12494604 | AA15: 2020 | AB15: Luanda | AC15: -7.6831475 | AE15: Huambo | AF15: =AVERAGEIF(Quadro_4[Províncias],AE15, Quadro_4[Valores percentuais do preço]) -> 25.055178 | AG15: =AVERAGEIF(Quadro_8[Províncias], AE15, Quadro_8[variação Percentual dp Volume]) -> 2.0766926 | AH15: Crescimento com Pressão de Preços | AJ15: Huambo | AK15: 3567.6597 | AL15: 3.0178639 | AN15: Huambo | AO15: -3.6638427 | AP15: 2.6470333 | AQ15: 2.8156967 | AR15: 12.529588 | AS15: -4.8861838 | AT15: 3.0178639 | AU15: =(1+Quadro8[[#This Row],[2021]]/100)*(1+Quadro8[[#This Row],[2022]]/100)*(1+Quadro8[[#This Row],[2023]]/100)*(1+Quadro8[[#This Row],[2024]]/100)*(1+Quadro8[[#This Row],[2025]]/100)-1 -> 0.16366695 | AV15: =_xlfn.STDEV.P(Quadro8[[#This Row],[2020]:[2025]]) -> 5.6635624 | AW15: =IF(Quadro8[[#This Row],[Desvio Padrão]]<=5.86, "Muito Consistente", IF(AND(AV15>5.86, AV15<=7.66), "Consistente", IF(AND(AV15>7.66, AV15<=9.98), "Instável", "Muito instável"))) -> Muito Consistente | AX15: =SLOPE(Quadro8[[#This Row],[2020]:[2025]], Modelagem!$AN$4:$AS$4) -> 0.58636494
